<?xml version="1.0"?>
<robot name="wippy">

    <material name="red">
        <color rgba="1 0 0 1"/>
    </material>
    <material name="green">
        <color rgba="0 1 0 1"/>
    </material>
    <material name="blue">
        <color rgba="0 0 1 1"/>
    </material>
    <material name="gray">
        <color rgba="0.5 0.5 0.5 1"/>
    </material>

    <link name="chassis">
        <visual>
            <origin rpy="0.0 0 0" xyz="0 0 0"/>
            <geometry>
                <mesh filename="package://urdfs/meshes/chassis.stl" scale="1 1 1"/>
            </geometry>
            <material name="red"/>
        </visual>
    </link>

    <link name="axle">
        <visual>
            <origin rpy="0.0 0 0" xyz="0 0 0"/>
            <geometry>
                <mesh filename="package://urdfs/meshes/axle.stl" scale="1 1 1"/>
            </geometry>
            <material name="gray"/>
        </visual>
    </link>

    <joint name="axle_joint" type="fixed">
        <parent link="chassis"/>
        <child link="axle"/>
        <origin rpy="0 0 0" xyz="0 0 0"/>
    </joint>

    <link name="wheel_left">
        <visual>
            <origin rpy="0.0 1.5708 0" xyz="0 0.085 0"/>
            <geometry>
                <mesh filename="package://urdfs/meshes/wheel.stl" scale="1 1 1"/>
            </geometry>
            <material name="green"/>
        </visual>
    </link>

    <joint name="wheel_left_joint" type="continuous">
        <parent link="axle"/>
        <child link="wheel_left"/>
        <origin rpy="0 0 0" xyz="0 0 0"/>
        <axis xyz="0 1 0"/>
    </joint>

    <link name="wheel_right">
        <visual>
            <origin rpy="0.0 1.5708 0" xyz="0 -0.085 0"/>
            <geometry>
                <mesh filename="package://urdfs/meshes/wheel.stl" scale="1 1 1"/>
            </geometry>
            <material name="green"/>
        </visual>
    </link>

    <joint name="wheel_right_joint" type="continuous">
        <parent link="axle"/>
        <child link="wheel_right"/>
        <origin rpy="0 0 0" xyz="0 0 0"/>
        <axis xyz="0 1 0"/>
    </joint>

    <link name="weight">
        <visual>
            <origin rpy="0.0 0 0" xyz="0 0 0.011"/>
            <geometry>
                <mesh filename="package://urdfs/meshes/weight.stl" scale="1 1 1"/>
            </geometry>
            <material name="blue"/>
        </visual>
    </link>

    <joint name="weight_joint" type="fixed">
        <parent link="axle"/>
        <child link="weight"/>
        <origin rpy="0 0 0" xyz="0 0 0"/>
    </joint>

    <gazebo reference="imu_link">
        <sensor type="imu" name="imu_sensor">
            <always_on>true</always_on>
            <update_rate>200</update_rate>
            <imu>
                <noise>
                    <type>gaussian</type>
                    <rate>
                        <mean>0.0</mean>
                        <stddev>0.01</stddev>
                    </rate>
                    <accel>
                        <mean>0.0</mean>
                        <stddev>0.01</stddev>
                    </accel>
                </noise>
            </imu>
            <plugin name="imu_plugin" filename="libgazebo_ros_imu.so">
                <robotNamespace>/imu</robotNamespace>
                <alwaysOn>true</alwaysOn>
                <updateRate>100</updateRate>
                <topicName>imu_data</topicName>
                <frameName>imu_link</frameName>
                <gaussianNoise>0.0</gaussianNoise>
            </plugin>
        </sensor>
    </gazebo>

</robot>